[2024-09-16T11:28:47.463+0000] {local_task_job_runner.py:123} INFO - ::group::Pre task execution logs
[2024-09-16T11:28:47.499+0000] {taskinstance.py:2612} INFO - Dependencies all met for dep_context=non-requeueable deps ti=<TaskInstance: test_alchemy.create_table_alchemy manual__2024-09-16T11:23:38.024113+00:00 [queued]>
[2024-09-16T11:28:47.528+0000] {taskinstance.py:2612} INFO - Dependencies all met for dep_context=requeueable deps ti=<TaskInstance: test_alchemy.create_table_alchemy manual__2024-09-16T11:23:38.024113+00:00 [queued]>
[2024-09-16T11:28:47.529+0000] {taskinstance.py:2865} INFO - Starting attempt 2 of 2
[2024-09-16T11:28:47.562+0000] {taskinstance.py:2888} INFO - Executing <Task(BashOperator): create_table_alchemy> on 2024-09-16 11:23:38.024113+00:00
[2024-09-16T11:28:47.575+0000] {warnings.py:112} WARNING - /home/***/.local/lib/python3.12/site-packages/***/task/task_runner/standard_task_runner.py:70: DeprecationWarning: This process (pid=1486) is multi-threaded, use of fork() may lead to deadlocks in the child.
  pid = os.fork()

[2024-09-16T11:28:47.579+0000] {standard_task_runner.py:72} INFO - Started process 1487 to run task
[2024-09-16T11:28:47.578+0000] {standard_task_runner.py:104} INFO - Running: ['***', 'tasks', 'run', 'test_alchemy', 'create_table_alchemy', 'manual__2024-09-16T11:23:38.024113+00:00', '--job-id', '17', '--raw', '--subdir', 'DAGS_FOLDER/test_alchemy_dags.py', '--cfg-path', '/tmp/tmpeqwhx93z']
[2024-09-16T11:28:47.581+0000] {standard_task_runner.py:105} INFO - Job 17: Subtask create_table_alchemy
[2024-09-16T11:28:47.669+0000] {task_command.py:467} INFO - Running <TaskInstance: test_alchemy.create_table_alchemy manual__2024-09-16T11:23:38.024113+00:00 [running]> on host 9978fde86398
[2024-09-16T11:28:47.853+0000] {taskinstance.py:3131} INFO - Exporting env vars: AIRFLOW_CTX_DAG_EMAIL='muhii.smta@gmail.com' AIRFLOW_CTX_DAG_OWNER='Muhii' AIRFLOW_CTX_DAG_ID='test_alchemy' AIRFLOW_CTX_TASK_ID='create_table_alchemy' AIRFLOW_CTX_EXECUTION_DATE='2024-09-16T11:23:38.024113+00:00' AIRFLOW_CTX_TRY_NUMBER='2' AIRFLOW_CTX_DAG_RUN_ID='manual__2024-09-16T11:23:38.024113+00:00'
[2024-09-16T11:28:47.855+0000] {taskinstance.py:731} INFO - ::endgroup::
[2024-09-16T11:28:47.900+0000] {subprocess.py:63} INFO - Tmp dir root location: /tmp
[2024-09-16T11:28:47.902+0000] {subprocess.py:75} INFO - Running command: ['/usr/bin/bash', '-c', 'python /opt/***/dags/script/test_alchemy.py']
[2024-09-16T11:28:47.928+0000] {subprocess.py:86} INFO - Output:
[2024-09-16T11:28:50.806+0000] {subprocess.py:93} INFO - /opt/***/dags/script/test_alchemy.py:12: RemovedIn20Warning: Deprecated API features detected! These feature(s) are not compatible with SQLAlchemy 2.0. To prevent incompatible upgrades prior to updating applications, ensure requirements files are pinned to "sqlalchemy<2.0". Set environment variable SQLALCHEMY_WARN_20=1 to show all deprecation warnings.  Set environment variable SQLALCHEMY_SILENCE_UBER_WARNING=1 to silence this message. (Background on SQLAlchemy 2.0 at: https://sqlalche.me/e/b8d9)
[2024-09-16T11:28:50.808+0000] {subprocess.py:93} INFO -   engine.execute(f"CREATE DATABASE IF NOT EXISTS {db_name}")
[2024-09-16T11:28:50.862+0000] {subprocess.py:93} INFO - Traceback (most recent call last):
[2024-09-16T11:28:50.864+0000] {subprocess.py:93} INFO -   File "/home/***/.local/lib/python3.12/site-packages/sqlalchemy/engine/base.py", line 1910, in _execute_context
[2024-09-16T11:28:50.865+0000] {subprocess.py:93} INFO -     self.dialect.do_execute(
[2024-09-16T11:28:50.866+0000] {subprocess.py:93} INFO -   File "/home/***/.local/lib/python3.12/site-packages/sqlalchemy/engine/default.py", line 736, in do_execute
[2024-09-16T11:28:50.867+0000] {subprocess.py:93} INFO -     cursor.execute(statement, parameters)
[2024-09-16T11:28:50.869+0000] {subprocess.py:93} INFO - psycopg2.errors.SyntaxError: syntax error at or near "NOT"
[2024-09-16T11:28:50.870+0000] {subprocess.py:93} INFO - LINE 1: CREATE DATABASE IF NOT EXISTS test_database
[2024-09-16T11:28:50.871+0000] {subprocess.py:93} INFO -                            ^
[2024-09-16T11:28:50.873+0000] {subprocess.py:93} INFO - 
[2024-09-16T11:28:50.874+0000] {subprocess.py:93} INFO - 
[2024-09-16T11:28:50.875+0000] {subprocess.py:93} INFO - The above exception was the direct cause of the following exception:
[2024-09-16T11:28:50.876+0000] {subprocess.py:93} INFO - 
[2024-09-16T11:28:50.877+0000] {subprocess.py:93} INFO - Traceback (most recent call last):
[2024-09-16T11:28:50.878+0000] {subprocess.py:93} INFO -   File "/opt/***/dags/script/test_alchemy.py", line 38, in <module>
[2024-09-16T11:28:50.879+0000] {subprocess.py:93} INFO -     main()
[2024-09-16T11:28:50.880+0000] {subprocess.py:93} INFO -   File "/opt/***/dags/script/test_alchemy.py", line 32, in main
[2024-09-16T11:28:50.881+0000] {subprocess.py:93} INFO -     loader.create_database(db_name)
[2024-09-16T11:28:50.882+0000] {subprocess.py:93} INFO -   File "/opt/***/dags/script/test_alchemy.py", line 12, in create_database
[2024-09-16T11:28:50.884+0000] {subprocess.py:93} INFO -     engine.execute(f"CREATE DATABASE IF NOT EXISTS {db_name}")
[2024-09-16T11:28:50.885+0000] {subprocess.py:93} INFO -   File "<string>", line 2, in execute
[2024-09-16T11:28:50.886+0000] {subprocess.py:93} INFO -   File "/home/***/.local/lib/python3.12/site-packages/sqlalchemy/util/deprecations.py", line 468, in warned
[2024-09-16T11:28:50.887+0000] {subprocess.py:93} INFO -     return fn(*args, **kwargs)
[2024-09-16T11:28:50.888+0000] {subprocess.py:93} INFO -            ^^^^^^^^^^^^^^^^^^^
[2024-09-16T11:28:50.889+0000] {subprocess.py:93} INFO -   File "/home/***/.local/lib/python3.12/site-packages/sqlalchemy/engine/base.py", line 3267, in execute
[2024-09-16T11:28:50.890+0000] {subprocess.py:93} INFO -     return connection.execute(statement, *multiparams, **params)
[2024-09-16T11:28:50.892+0000] {subprocess.py:93} INFO -            ^^^^^^^^^^^^^^^^^^^^^^^^^^^^^^^^^^^^^^^^^^^^^^^^^^^^^
[2024-09-16T11:28:50.893+0000] {subprocess.py:93} INFO -   File "/home/***/.local/lib/python3.12/site-packages/sqlalchemy/engine/base.py", line 1370, in execute
[2024-09-16T11:28:50.894+0000] {subprocess.py:93} INFO -     return self._exec_driver_sql(
[2024-09-16T11:28:50.895+0000] {subprocess.py:93} INFO -            ^^^^^^^^^^^^^^^^^^^^^^
[2024-09-16T11:28:50.896+0000] {subprocess.py:93} INFO -   File "/home/***/.local/lib/python3.12/site-packages/sqlalchemy/engine/base.py", line 1674, in _exec_driver_sql
[2024-09-16T11:28:50.896+0000] {subprocess.py:93} INFO -     ret = self._execute_context(
[2024-09-16T11:28:50.898+0000] {subprocess.py:93} INFO -           ^^^^^^^^^^^^^^^^^^^^^^
[2024-09-16T11:28:50.898+0000] {subprocess.py:93} INFO -   File "/home/***/.local/lib/python3.12/site-packages/sqlalchemy/engine/base.py", line 1953, in _execute_context
[2024-09-16T11:28:50.899+0000] {subprocess.py:93} INFO -     self._handle_dbapi_exception(
[2024-09-16T11:28:50.900+0000] {subprocess.py:93} INFO -   File "/home/***/.local/lib/python3.12/site-packages/sqlalchemy/engine/base.py", line 2134, in _handle_dbapi_exception
[2024-09-16T11:28:50.901+0000] {subprocess.py:93} INFO -     util.raise_(
[2024-09-16T11:28:50.902+0000] {subprocess.py:93} INFO -   File "/home/***/.local/lib/python3.12/site-packages/sqlalchemy/util/compat.py", line 211, in raise_
[2024-09-16T11:28:50.903+0000] {subprocess.py:93} INFO -     raise exception
[2024-09-16T11:28:50.904+0000] {subprocess.py:93} INFO -   File "/home/***/.local/lib/python3.12/site-packages/sqlalchemy/engine/base.py", line 1910, in _execute_context
[2024-09-16T11:28:50.905+0000] {subprocess.py:93} INFO -     self.dialect.do_execute(
[2024-09-16T11:28:50.906+0000] {subprocess.py:93} INFO -   File "/home/***/.local/lib/python3.12/site-packages/sqlalchemy/engine/default.py", line 736, in do_execute
[2024-09-16T11:28:50.907+0000] {subprocess.py:93} INFO -     cursor.execute(statement, parameters)
[2024-09-16T11:28:50.908+0000] {subprocess.py:93} INFO - sqlalchemy.exc.ProgrammingError: (psycopg2.errors.SyntaxError) syntax error at or near "NOT"
[2024-09-16T11:28:50.909+0000] {subprocess.py:93} INFO - LINE 1: CREATE DATABASE IF NOT EXISTS test_database
[2024-09-16T11:28:50.910+0000] {subprocess.py:93} INFO -                            ^
[2024-09-16T11:28:50.911+0000] {subprocess.py:93} INFO - 
[2024-09-16T11:28:50.912+0000] {subprocess.py:93} INFO - [SQL: CREATE DATABASE IF NOT EXISTS test_database]
[2024-09-16T11:28:50.913+0000] {subprocess.py:93} INFO - (Background on this error at: https://sqlalche.me/e/14/f405)
[2024-09-16T11:28:51.084+0000] {subprocess.py:97} INFO - Command exited with return code 1
[2024-09-16T11:28:51.110+0000] {taskinstance.py:3310} ERROR - Task failed with exception
Traceback (most recent call last):
  File "/home/airflow/.local/lib/python3.12/site-packages/airflow/models/taskinstance.py", line 767, in _execute_task
    result = _execute_callable(context=context, **execute_callable_kwargs)
             ^^^^^^^^^^^^^^^^^^^^^^^^^^^^^^^^^^^^^^^^^^^^^^^^^^^^^^^^^^^^^
  File "/home/airflow/.local/lib/python3.12/site-packages/airflow/models/taskinstance.py", line 733, in _execute_callable
    return ExecutionCallableRunner(
           ^^^^^^^^^^^^^^^^^^^^^^^^
  File "/home/airflow/.local/lib/python3.12/site-packages/airflow/utils/operator_helpers.py", line 252, in run
    return self.func(*args, **kwargs)
           ^^^^^^^^^^^^^^^^^^^^^^^^^^
  File "/home/airflow/.local/lib/python3.12/site-packages/airflow/models/baseoperator.py", line 406, in wrapper
    return func(self, *args, **kwargs)
           ^^^^^^^^^^^^^^^^^^^^^^^^^^^
  File "/home/airflow/.local/lib/python3.12/site-packages/airflow/operators/bash.py", line 249, in execute
    raise AirflowException(
airflow.exceptions.AirflowException: Bash command failed. The command returned a non-zero exit code 1.
[2024-09-16T11:28:51.121+0000] {taskinstance.py:1225} INFO - Marking task as FAILED. dag_id=test_alchemy, task_id=create_table_alchemy, run_id=manual__2024-09-16T11:23:38.024113+00:00, execution_date=20240916T112338, start_date=20240916T112847, end_date=20240916T112851
[2024-09-16T11:28:51.149+0000] {taskinstance.py:340} INFO - ::group::Post task execution logs
[2024-09-16T11:28:51.151+0000] {standard_task_runner.py:124} ERROR - Failed to execute job 17 for task create_table_alchemy (Bash command failed. The command returned a non-zero exit code 1.; 1487)
Traceback (most recent call last):
  File "/home/airflow/.local/lib/python3.12/site-packages/airflow/task/task_runner/standard_task_runner.py", line 117, in _start_by_fork
    ret = args.func(args, dag=self.dag)
          ^^^^^^^^^^^^^^^^^^^^^^^^^^^^^
  File "/home/airflow/.local/lib/python3.12/site-packages/airflow/cli/cli_config.py", line 49, in command
    return func(*args, **kwargs)
           ^^^^^^^^^^^^^^^^^^^^^
  File "/home/airflow/.local/lib/python3.12/site-packages/airflow/utils/cli.py", line 115, in wrapper
    return f(*args, **kwargs)
           ^^^^^^^^^^^^^^^^^^
  File "/home/airflow/.local/lib/python3.12/site-packages/airflow/cli/commands/task_command.py", line 483, in task_run
    task_return_code = _run_task_by_selected_method(args, _dag, ti)
                       ^^^^^^^^^^^^^^^^^^^^^^^^^^^^^^^^^^^^^^^^^^^^
  File "/home/airflow/.local/lib/python3.12/site-packages/airflow/cli/commands/task_command.py", line 256, in _run_task_by_selected_method
    return _run_raw_task(args, ti)
           ^^^^^^^^^^^^^^^^^^^^^^^
  File "/home/airflow/.local/lib/python3.12/site-packages/airflow/cli/commands/task_command.py", line 341, in _run_raw_task
    return ti._run_raw_task(
           ^^^^^^^^^^^^^^^^^
  File "/home/airflow/.local/lib/python3.12/site-packages/airflow/utils/session.py", line 97, in wrapper
    return func(*args, session=session, **kwargs)
           ^^^^^^^^^^^^^^^^^^^^^^^^^^^^^^^^^^^^^^
  File "/home/airflow/.local/lib/python3.12/site-packages/airflow/models/taskinstance.py", line 3004, in _run_raw_task
    return _run_raw_task(
           ^^^^^^^^^^^^^^
  File "/home/airflow/.local/lib/python3.12/site-packages/airflow/models/taskinstance.py", line 273, in _run_raw_task
    TaskInstance._execute_task_with_callbacks(
  File "/home/airflow/.local/lib/python3.12/site-packages/airflow/models/taskinstance.py", line 3158, in _execute_task_with_callbacks
    result = self._execute_task(context, task_orig)
             ^^^^^^^^^^^^^^^^^^^^^^^^^^^^^^^^^^^^^^
  File "/home/airflow/.local/lib/python3.12/site-packages/airflow/models/taskinstance.py", line 3182, in _execute_task
    return _execute_task(self, context, task_orig)
           ^^^^^^^^^^^^^^^^^^^^^^^^^^^^^^^^^^^^^^^
  File "/home/airflow/.local/lib/python3.12/site-packages/airflow/models/taskinstance.py", line 767, in _execute_task
    result = _execute_callable(context=context, **execute_callable_kwargs)
             ^^^^^^^^^^^^^^^^^^^^^^^^^^^^^^^^^^^^^^^^^^^^^^^^^^^^^^^^^^^^^
  File "/home/airflow/.local/lib/python3.12/site-packages/airflow/models/taskinstance.py", line 733, in _execute_callable
    return ExecutionCallableRunner(
           ^^^^^^^^^^^^^^^^^^^^^^^^
  File "/home/airflow/.local/lib/python3.12/site-packages/airflow/utils/operator_helpers.py", line 252, in run
    return self.func(*args, **kwargs)
           ^^^^^^^^^^^^^^^^^^^^^^^^^^
  File "/home/airflow/.local/lib/python3.12/site-packages/airflow/models/baseoperator.py", line 406, in wrapper
    return func(self, *args, **kwargs)
           ^^^^^^^^^^^^^^^^^^^^^^^^^^^
  File "/home/airflow/.local/lib/python3.12/site-packages/airflow/operators/bash.py", line 249, in execute
    raise AirflowException(
airflow.exceptions.AirflowException: Bash command failed. The command returned a non-zero exit code 1.
[2024-09-16T11:28:51.195+0000] {local_task_job_runner.py:266} INFO - Task exited with return code 1
[2024-09-16T11:28:51.244+0000] {taskinstance.py:3900} INFO - 0 downstream tasks scheduled from follow-on schedule check
[2024-09-16T11:28:51.252+0000] {local_task_job_runner.py:245} INFO - ::endgroup::
