[2024-09-12T18:34:25.864+0000] {local_task_job_runner.py:123} INFO - ::group::Pre task execution logs
[2024-09-12T18:34:25.900+0000] {taskinstance.py:2612} INFO - Dependencies all met for dep_context=non-requeueable deps ti=<TaskInstance: test_airflow.testAirflow manual__2024-09-12T18:34:21.525914+00:00 [queued]>
[2024-09-12T18:34:25.919+0000] {taskinstance.py:2612} INFO - Dependencies all met for dep_context=requeueable deps ti=<TaskInstance: test_airflow.testAirflow manual__2024-09-12T18:34:21.525914+00:00 [queued]>
[2024-09-12T18:34:25.920+0000] {taskinstance.py:2865} INFO - Starting attempt 1 of 2
[2024-09-12T18:34:25.952+0000] {taskinstance.py:2888} INFO - Executing <Task(BashOperator): testAirflow> on 2024-09-12 18:34:21.525914+00:00
[2024-09-12T18:34:25.964+0000] {warnings.py:112} WARNING - /home/***/.local/lib/python3.12/site-packages/***/task/task_runner/standard_task_runner.py:70: DeprecationWarning: This process (pid=250) is multi-threaded, use of fork() may lead to deadlocks in the child.
  pid = os.fork()

[2024-09-12T18:34:25.967+0000] {standard_task_runner.py:72} INFO - Started process 251 to run task
[2024-09-12T18:34:25.968+0000] {standard_task_runner.py:104} INFO - Running: ['***', 'tasks', 'run', 'test_***', 'testAirflow', 'manual__2024-09-12T18:34:21.525914+00:00', '--job-id', '43', '--raw', '--subdir', 'DAGS_FOLDER/test_dags.py', '--cfg-path', '/tmp/tmpn6pn5_ac']
[2024-09-12T18:34:25.970+0000] {standard_task_runner.py:105} INFO - Job 43: Subtask testAirflow
[2024-09-12T18:34:26.059+0000] {task_command.py:467} INFO - Running <TaskInstance: test_airflow.testAirflow manual__2024-09-12T18:34:21.525914+00:00 [running]> on host 9c5d837b6f3b
[2024-09-12T18:34:26.215+0000] {taskinstance.py:3131} INFO - Exporting env vars: AIRFLOW_CTX_DAG_EMAIL='muhii.smta@gmail.com' AIRFLOW_CTX_DAG_OWNER='Muhii' AIRFLOW_CTX_DAG_ID='test_***' AIRFLOW_CTX_TASK_ID='testAirflow' AIRFLOW_CTX_EXECUTION_DATE='2024-09-12T18:34:21.525914+00:00' AIRFLOW_CTX_TRY_NUMBER='1' AIRFLOW_CTX_DAG_RUN_ID='manual__2024-09-12T18:34:21.525914+00:00'
[2024-09-12T18:34:26.217+0000] {taskinstance.py:731} INFO - ::endgroup::
[2024-09-12T18:34:26.243+0000] {subprocess.py:63} INFO - Tmp dir root location: /tmp
[2024-09-12T18:34:26.244+0000] {subprocess.py:75} INFO - Running command: ['/usr/bin/bash', '-c', 'python /opt/***/dags/script/testAirflow.py']
[2024-09-12T18:34:26.263+0000] {subprocess.py:86} INFO - Output:
[2024-09-12T18:34:28.368+0000] {subprocess.py:93} INFO - Traceback (most recent call last):
[2024-09-12T18:34:28.370+0000] {subprocess.py:93} INFO -   File "/opt/***/dags/script/testAirflow.py", line 5, in <module>
[2024-09-12T18:34:28.375+0000] {subprocess.py:93} INFO -     df = pd.read_csv(path_csv)
[2024-09-12T18:34:28.376+0000] {subprocess.py:93} INFO -          ^^^^^^^^^^^^^^^^^^^^^
[2024-09-12T18:34:28.377+0000] {subprocess.py:93} INFO -   File "/home/***/.local/lib/python3.12/site-packages/pandas/io/parsers/readers.py", line 1026, in read_csv
[2024-09-12T18:34:28.379+0000] {subprocess.py:93} INFO -     return _read(filepath_or_buffer, kwds)
[2024-09-12T18:34:28.380+0000] {subprocess.py:93} INFO -            ^^^^^^^^^^^^^^^^^^^^^^^^^^^^^^^
[2024-09-12T18:34:28.381+0000] {subprocess.py:93} INFO -   File "/home/***/.local/lib/python3.12/site-packages/pandas/io/parsers/readers.py", line 620, in _read
[2024-09-12T18:34:28.382+0000] {subprocess.py:93} INFO -     parser = TextFileReader(filepath_or_buffer, **kwds)
[2024-09-12T18:34:28.384+0000] {subprocess.py:93} INFO -              ^^^^^^^^^^^^^^^^^^^^^^^^^^^^^^^^^^^^^^^^^^
[2024-09-12T18:34:28.385+0000] {subprocess.py:93} INFO -   File "/home/***/.local/lib/python3.12/site-packages/pandas/io/parsers/readers.py", line 1620, in __init__
[2024-09-12T18:34:28.386+0000] {subprocess.py:93} INFO -     self._engine = self._make_engine(f, self.engine)
[2024-09-12T18:34:28.387+0000] {subprocess.py:93} INFO -                    ^^^^^^^^^^^^^^^^^^^^^^^^^^^^^^^^^
[2024-09-12T18:34:28.388+0000] {subprocess.py:93} INFO -   File "/home/***/.local/lib/python3.12/site-packages/pandas/io/parsers/readers.py", line 1880, in _make_engine
[2024-09-12T18:34:28.390+0000] {subprocess.py:93} INFO -     self.handles = get_handle(
[2024-09-12T18:34:28.391+0000] {subprocess.py:93} INFO -                    ^^^^^^^^^^^
[2024-09-12T18:34:28.392+0000] {subprocess.py:93} INFO -   File "/home/***/.local/lib/python3.12/site-packages/pandas/io/common.py", line 873, in get_handle
[2024-09-12T18:34:28.393+0000] {subprocess.py:93} INFO -     handle = open(
[2024-09-12T18:34:28.394+0000] {subprocess.py:93} INFO -              ^^^^^
[2024-09-12T18:34:28.395+0000] {subprocess.py:93} INFO - FileNotFoundError: [Errno 2] No such file or directory: '/opt/***/dags/input/customer.csv'
[2024-09-12T18:34:28.511+0000] {subprocess.py:97} INFO - Command exited with return code 1
[2024-09-12T18:34:28.546+0000] {taskinstance.py:3310} ERROR - Task failed with exception
Traceback (most recent call last):
  File "/home/airflow/.local/lib/python3.12/site-packages/airflow/models/taskinstance.py", line 767, in _execute_task
    result = _execute_callable(context=context, **execute_callable_kwargs)
             ^^^^^^^^^^^^^^^^^^^^^^^^^^^^^^^^^^^^^^^^^^^^^^^^^^^^^^^^^^^^^
  File "/home/airflow/.local/lib/python3.12/site-packages/airflow/models/taskinstance.py", line 733, in _execute_callable
    return ExecutionCallableRunner(
           ^^^^^^^^^^^^^^^^^^^^^^^^
  File "/home/airflow/.local/lib/python3.12/site-packages/airflow/utils/operator_helpers.py", line 252, in run
    return self.func(*args, **kwargs)
           ^^^^^^^^^^^^^^^^^^^^^^^^^^
  File "/home/airflow/.local/lib/python3.12/site-packages/airflow/models/baseoperator.py", line 406, in wrapper
    return func(self, *args, **kwargs)
           ^^^^^^^^^^^^^^^^^^^^^^^^^^^
  File "/home/airflow/.local/lib/python3.12/site-packages/airflow/operators/bash.py", line 249, in execute
    raise AirflowException(
airflow.exceptions.AirflowException: Bash command failed. The command returned a non-zero exit code 1.
[2024-09-12T18:34:28.564+0000] {taskinstance.py:1225} INFO - Marking task as UP_FOR_RETRY. dag_id=test_***, task_id=testAirflow, run_id=manual__2024-09-12T18:34:21.525914+00:00, execution_date=20240912T183421, start_date=20240912T183425, end_date=20240912T183428
[2024-09-12T18:34:28.609+0000] {taskinstance.py:340} INFO - ::group::Post task execution logs
[2024-09-12T18:34:28.611+0000] {standard_task_runner.py:124} ERROR - Failed to execute job 43 for task testAirflow (Bash command failed. The command returned a non-zero exit code 1.; 251)
Traceback (most recent call last):
  File "/home/airflow/.local/lib/python3.12/site-packages/airflow/task/task_runner/standard_task_runner.py", line 117, in _start_by_fork
    ret = args.func(args, dag=self.dag)
          ^^^^^^^^^^^^^^^^^^^^^^^^^^^^^
  File "/home/airflow/.local/lib/python3.12/site-packages/airflow/cli/cli_config.py", line 49, in command
    return func(*args, **kwargs)
           ^^^^^^^^^^^^^^^^^^^^^
  File "/home/airflow/.local/lib/python3.12/site-packages/airflow/utils/cli.py", line 115, in wrapper
    return f(*args, **kwargs)
           ^^^^^^^^^^^^^^^^^^
  File "/home/airflow/.local/lib/python3.12/site-packages/airflow/cli/commands/task_command.py", line 483, in task_run
    task_return_code = _run_task_by_selected_method(args, _dag, ti)
                       ^^^^^^^^^^^^^^^^^^^^^^^^^^^^^^^^^^^^^^^^^^^^
  File "/home/airflow/.local/lib/python3.12/site-packages/airflow/cli/commands/task_command.py", line 256, in _run_task_by_selected_method
    return _run_raw_task(args, ti)
           ^^^^^^^^^^^^^^^^^^^^^^^
  File "/home/airflow/.local/lib/python3.12/site-packages/airflow/cli/commands/task_command.py", line 341, in _run_raw_task
    return ti._run_raw_task(
           ^^^^^^^^^^^^^^^^^
  File "/home/airflow/.local/lib/python3.12/site-packages/airflow/utils/session.py", line 97, in wrapper
    return func(*args, session=session, **kwargs)
           ^^^^^^^^^^^^^^^^^^^^^^^^^^^^^^^^^^^^^^
  File "/home/airflow/.local/lib/python3.12/site-packages/airflow/models/taskinstance.py", line 3004, in _run_raw_task
    return _run_raw_task(
           ^^^^^^^^^^^^^^
  File "/home/airflow/.local/lib/python3.12/site-packages/airflow/models/taskinstance.py", line 273, in _run_raw_task
    TaskInstance._execute_task_with_callbacks(
  File "/home/airflow/.local/lib/python3.12/site-packages/airflow/models/taskinstance.py", line 3158, in _execute_task_with_callbacks
    result = self._execute_task(context, task_orig)
             ^^^^^^^^^^^^^^^^^^^^^^^^^^^^^^^^^^^^^^
  File "/home/airflow/.local/lib/python3.12/site-packages/airflow/models/taskinstance.py", line 3182, in _execute_task
    return _execute_task(self, context, task_orig)
           ^^^^^^^^^^^^^^^^^^^^^^^^^^^^^^^^^^^^^^^
  File "/home/airflow/.local/lib/python3.12/site-packages/airflow/models/taskinstance.py", line 767, in _execute_task
    result = _execute_callable(context=context, **execute_callable_kwargs)
             ^^^^^^^^^^^^^^^^^^^^^^^^^^^^^^^^^^^^^^^^^^^^^^^^^^^^^^^^^^^^^
  File "/home/airflow/.local/lib/python3.12/site-packages/airflow/models/taskinstance.py", line 733, in _execute_callable
    return ExecutionCallableRunner(
           ^^^^^^^^^^^^^^^^^^^^^^^^
  File "/home/airflow/.local/lib/python3.12/site-packages/airflow/utils/operator_helpers.py", line 252, in run
    return self.func(*args, **kwargs)
           ^^^^^^^^^^^^^^^^^^^^^^^^^^
  File "/home/airflow/.local/lib/python3.12/site-packages/airflow/models/baseoperator.py", line 406, in wrapper
    return func(self, *args, **kwargs)
           ^^^^^^^^^^^^^^^^^^^^^^^^^^^
  File "/home/airflow/.local/lib/python3.12/site-packages/airflow/operators/bash.py", line 249, in execute
    raise AirflowException(
airflow.exceptions.AirflowException: Bash command failed. The command returned a non-zero exit code 1.
[2024-09-12T18:34:28.652+0000] {local_task_job_runner.py:266} INFO - Task exited with return code 1
[2024-09-12T18:34:28.709+0000] {taskinstance.py:3900} INFO - 0 downstream tasks scheduled from follow-on schedule check
[2024-09-12T18:34:28.714+0000] {local_task_job_runner.py:245} INFO - ::endgroup::
