[2024-09-16T15:52:52.810+0000] {local_task_job_runner.py:123} INFO - ::group::Pre task execution logs
[2024-09-16T15:52:52.845+0000] {taskinstance.py:2612} INFO - Dependencies all met for dep_context=non-requeueable deps ti=<TaskInstance: test_load_database.task_etl scheduled__2024-07-21T00:00:00+00:00 [queued]>
[2024-09-16T15:52:52.862+0000] {taskinstance.py:2612} INFO - Dependencies all met for dep_context=requeueable deps ti=<TaskInstance: test_load_database.task_etl scheduled__2024-07-21T00:00:00+00:00 [queued]>
[2024-09-16T15:52:52.863+0000] {taskinstance.py:2865} INFO - Starting attempt 3 of 4
[2024-09-16T15:52:52.889+0000] {taskinstance.py:2888} INFO - Executing <Task(PythonOperator): task_etl> on 2024-07-21 00:00:00+00:00
[2024-09-16T15:52:52.903+0000] {warnings.py:112} WARNING - /home/***/.local/lib/python3.12/site-packages/***/task/task_runner/standard_task_runner.py:70: DeprecationWarning: This process (pid=1362) is multi-threaded, use of fork() may lead to deadlocks in the child.
  pid = os.fork()

[2024-09-16T15:52:52.906+0000] {standard_task_runner.py:72} INFO - Started process 1364 to run task
[2024-09-16T15:52:52.905+0000] {standard_task_runner.py:104} INFO - Running: ['***', 'tasks', 'run', 'test_load_database', 'task_etl', 'scheduled__2024-07-21T00:00:00+00:00', '--job-id', '33', '--raw', '--subdir', 'DAGS_FOLDER/test_load_db_dags.py', '--cfg-path', '/tmp/tmpeo7_wb8s']
[2024-09-16T15:52:52.909+0000] {standard_task_runner.py:105} INFO - Job 33: Subtask task_etl
[2024-09-16T15:52:52.994+0000] {task_command.py:467} INFO - Running <TaskInstance: test_load_database.task_etl scheduled__2024-07-21T00:00:00+00:00 [running]> on host e54c4d73c780
[2024-09-16T15:52:53.527+0000] {taskinstance.py:3131} INFO - Exporting env vars: AIRFLOW_CTX_DAG_EMAIL='muhii.smta@gmail.com' AIRFLOW_CTX_DAG_OWNER='Muhii' AIRFLOW_CTX_DAG_ID='test_load_database' AIRFLOW_CTX_TASK_ID='task_etl' AIRFLOW_CTX_EXECUTION_DATE='2024-07-21T00:00:00+00:00' AIRFLOW_CTX_TRY_NUMBER='3' AIRFLOW_CTX_DAG_RUN_ID='scheduled__2024-07-21T00:00:00+00:00'
[2024-09-16T15:52:53.529+0000] {taskinstance.py:731} INFO - ::endgroup::
[2024-09-16T15:52:54.262+0000] {warnings.py:112} WARNING - /opt/***/dags/test_load_db_dags.py:40: UserWarning: pandas only supports SQLAlchemy connectable (engine/connection) or database string URI or sqlite3 DBAPI2 connection. Other DBAPI2 objects are not tested. Please consider using SQLAlchemy.
  df_idn = sqldf(''' select * from df where country='Australia' ''')

[2024-09-16T15:52:54.267+0000] {taskinstance.py:3310} ERROR - Task failed with exception
Traceback (most recent call last):
  File "/home/airflow/.local/lib/python3.12/site-packages/airflow/models/taskinstance.py", line 767, in _execute_task
    result = _execute_callable(context=context, **execute_callable_kwargs)
             ^^^^^^^^^^^^^^^^^^^^^^^^^^^^^^^^^^^^^^^^^^^^^^^^^^^^^^^^^^^^^
  File "/home/airflow/.local/lib/python3.12/site-packages/airflow/models/taskinstance.py", line 733, in _execute_callable
    return ExecutionCallableRunner(
           ^^^^^^^^^^^^^^^^^^^^^^^^
  File "/home/airflow/.local/lib/python3.12/site-packages/airflow/utils/operator_helpers.py", line 252, in run
    return self.func(*args, **kwargs)
           ^^^^^^^^^^^^^^^^^^^^^^^^^^
  File "/home/airflow/.local/lib/python3.12/site-packages/airflow/models/baseoperator.py", line 406, in wrapper
    return func(self, *args, **kwargs)
           ^^^^^^^^^^^^^^^^^^^^^^^^^^^
  File "/home/airflow/.local/lib/python3.12/site-packages/airflow/operators/python.py", line 238, in execute
    return_value = self.execute_callable()
                   ^^^^^^^^^^^^^^^^^^^^^^^
  File "/home/airflow/.local/lib/python3.12/site-packages/airflow/operators/python.py", line 256, in execute_callable
    return runner.run(*self.op_args, **self.op_kwargs)
           ^^^^^^^^^^^^^^^^^^^^^^^^^^^^^^^^^^^^^^^^^^^
  File "/home/airflow/.local/lib/python3.12/site-packages/airflow/utils/operator_helpers.py", line 252, in run
    return self.func(*args, **kwargs)
           ^^^^^^^^^^^^^^^^^^^^^^^^^^
  File "/opt/airflow/dags/test_load_db_dags.py", line 40, in etl_data
    df_idn = sqldf(''' select * from df where country='Australia' ''')
             ^^^^^^^^^^^^^^^^^^^^^^^^^^^^^^^^^^^^^^^^^^^^^^^^^^^^^^^^^
  File "/home/airflow/.local/lib/python3.12/site-packages/pandasql/sqldf.py", line 156, in sqldf
    return PandaSQL(db_uri)(query, env)
           ^^^^^^^^^^^^^^^^^^^^^^^^^^^^
  File "/home/airflow/.local/lib/python3.12/site-packages/pandasql/sqldf.py", line 58, in __call__
    write_table(env[table_name], table_name, conn)
  File "/home/airflow/.local/lib/python3.12/site-packages/pandasql/sqldf.py", line 120, in write_table
    to_sql(df, name=tablename, con=conn,
  File "/home/airflow/.local/lib/python3.12/site-packages/pandas/io/sql.py", line 842, in to_sql
    return pandas_sql.to_sql(
           ^^^^^^^^^^^^^^^^^^
  File "/home/airflow/.local/lib/python3.12/site-packages/pandas/io/sql.py", line 2850, in to_sql
    table.create()
  File "/home/airflow/.local/lib/python3.12/site-packages/pandas/io/sql.py", line 984, in create
    if self.exists():
       ^^^^^^^^^^^^^
  File "/home/airflow/.local/lib/python3.12/site-packages/pandas/io/sql.py", line 970, in exists
    return self.pd_sql.has_table(self.name, self.schema)
           ^^^^^^^^^^^^^^^^^^^^^^^^^^^^^^^^^^^^^^^^^^^^^
  File "/home/airflow/.local/lib/python3.12/site-packages/pandas/io/sql.py", line 2865, in has_table
    return len(self.execute(query, [name]).fetchall()) > 0
               ^^^^^^^^^^^^^^^^^^^^^^^^^^^
  File "/home/airflow/.local/lib/python3.12/site-packages/pandas/io/sql.py", line 2672, in execute
    cur = self.con.cursor()
          ^^^^^^^^^^^^^^^
AttributeError: 'Connection' object has no attribute 'cursor'
[2024-09-16T15:52:54.301+0000] {taskinstance.py:1225} INFO - Marking task as UP_FOR_RETRY. dag_id=test_load_database, task_id=task_etl, run_id=scheduled__2024-07-21T00:00:00+00:00, execution_date=20240721T000000, start_date=20240916T155252, end_date=20240916T155254
[2024-09-16T15:52:54.350+0000] {taskinstance.py:340} INFO - ::group::Post task execution logs
[2024-09-16T15:52:54.351+0000] {standard_task_runner.py:124} ERROR - Failed to execute job 33 for task task_etl ('Connection' object has no attribute 'cursor'; 1364)
Traceback (most recent call last):
  File "/home/airflow/.local/lib/python3.12/site-packages/airflow/task/task_runner/standard_task_runner.py", line 117, in _start_by_fork
    ret = args.func(args, dag=self.dag)
          ^^^^^^^^^^^^^^^^^^^^^^^^^^^^^
  File "/home/airflow/.local/lib/python3.12/site-packages/airflow/cli/cli_config.py", line 49, in command
    return func(*args, **kwargs)
           ^^^^^^^^^^^^^^^^^^^^^
  File "/home/airflow/.local/lib/python3.12/site-packages/airflow/utils/cli.py", line 115, in wrapper
    return f(*args, **kwargs)
           ^^^^^^^^^^^^^^^^^^
  File "/home/airflow/.local/lib/python3.12/site-packages/airflow/cli/commands/task_command.py", line 483, in task_run
    task_return_code = _run_task_by_selected_method(args, _dag, ti)
                       ^^^^^^^^^^^^^^^^^^^^^^^^^^^^^^^^^^^^^^^^^^^^
  File "/home/airflow/.local/lib/python3.12/site-packages/airflow/cli/commands/task_command.py", line 256, in _run_task_by_selected_method
    return _run_raw_task(args, ti)
           ^^^^^^^^^^^^^^^^^^^^^^^
  File "/home/airflow/.local/lib/python3.12/site-packages/airflow/cli/commands/task_command.py", line 341, in _run_raw_task
    return ti._run_raw_task(
           ^^^^^^^^^^^^^^^^^
  File "/home/airflow/.local/lib/python3.12/site-packages/airflow/utils/session.py", line 97, in wrapper
    return func(*args, session=session, **kwargs)
           ^^^^^^^^^^^^^^^^^^^^^^^^^^^^^^^^^^^^^^
  File "/home/airflow/.local/lib/python3.12/site-packages/airflow/models/taskinstance.py", line 3004, in _run_raw_task
    return _run_raw_task(
           ^^^^^^^^^^^^^^
  File "/home/airflow/.local/lib/python3.12/site-packages/airflow/models/taskinstance.py", line 273, in _run_raw_task
    TaskInstance._execute_task_with_callbacks(
  File "/home/airflow/.local/lib/python3.12/site-packages/airflow/models/taskinstance.py", line 3158, in _execute_task_with_callbacks
    result = self._execute_task(context, task_orig)
             ^^^^^^^^^^^^^^^^^^^^^^^^^^^^^^^^^^^^^^
  File "/home/airflow/.local/lib/python3.12/site-packages/airflow/models/taskinstance.py", line 3182, in _execute_task
    return _execute_task(self, context, task_orig)
           ^^^^^^^^^^^^^^^^^^^^^^^^^^^^^^^^^^^^^^^
  File "/home/airflow/.local/lib/python3.12/site-packages/airflow/models/taskinstance.py", line 767, in _execute_task
    result = _execute_callable(context=context, **execute_callable_kwargs)
             ^^^^^^^^^^^^^^^^^^^^^^^^^^^^^^^^^^^^^^^^^^^^^^^^^^^^^^^^^^^^^
  File "/home/airflow/.local/lib/python3.12/site-packages/airflow/models/taskinstance.py", line 733, in _execute_callable
    return ExecutionCallableRunner(
           ^^^^^^^^^^^^^^^^^^^^^^^^
  File "/home/airflow/.local/lib/python3.12/site-packages/airflow/utils/operator_helpers.py", line 252, in run
    return self.func(*args, **kwargs)
           ^^^^^^^^^^^^^^^^^^^^^^^^^^
  File "/home/airflow/.local/lib/python3.12/site-packages/airflow/models/baseoperator.py", line 406, in wrapper
    return func(self, *args, **kwargs)
           ^^^^^^^^^^^^^^^^^^^^^^^^^^^
  File "/home/airflow/.local/lib/python3.12/site-packages/airflow/operators/python.py", line 238, in execute
    return_value = self.execute_callable()
                   ^^^^^^^^^^^^^^^^^^^^^^^
  File "/home/airflow/.local/lib/python3.12/site-packages/airflow/operators/python.py", line 256, in execute_callable
    return runner.run(*self.op_args, **self.op_kwargs)
           ^^^^^^^^^^^^^^^^^^^^^^^^^^^^^^^^^^^^^^^^^^^
  File "/home/airflow/.local/lib/python3.12/site-packages/airflow/utils/operator_helpers.py", line 252, in run
    return self.func(*args, **kwargs)
           ^^^^^^^^^^^^^^^^^^^^^^^^^^
  File "/opt/airflow/dags/test_load_db_dags.py", line 40, in etl_data
    df_idn = sqldf(''' select * from df where country='Australia' ''')
             ^^^^^^^^^^^^^^^^^^^^^^^^^^^^^^^^^^^^^^^^^^^^^^^^^^^^^^^^^
  File "/home/airflow/.local/lib/python3.12/site-packages/pandasql/sqldf.py", line 156, in sqldf
    return PandaSQL(db_uri)(query, env)
           ^^^^^^^^^^^^^^^^^^^^^^^^^^^^
  File "/home/airflow/.local/lib/python3.12/site-packages/pandasql/sqldf.py", line 58, in __call__
    write_table(env[table_name], table_name, conn)
  File "/home/airflow/.local/lib/python3.12/site-packages/pandasql/sqldf.py", line 120, in write_table
    to_sql(df, name=tablename, con=conn,
  File "/home/airflow/.local/lib/python3.12/site-packages/pandas/io/sql.py", line 842, in to_sql
    return pandas_sql.to_sql(
           ^^^^^^^^^^^^^^^^^^
  File "/home/airflow/.local/lib/python3.12/site-packages/pandas/io/sql.py", line 2850, in to_sql
    table.create()
  File "/home/airflow/.local/lib/python3.12/site-packages/pandas/io/sql.py", line 984, in create
    if self.exists():
       ^^^^^^^^^^^^^
  File "/home/airflow/.local/lib/python3.12/site-packages/pandas/io/sql.py", line 970, in exists
    return self.pd_sql.has_table(self.name, self.schema)
           ^^^^^^^^^^^^^^^^^^^^^^^^^^^^^^^^^^^^^^^^^^^^^
  File "/home/airflow/.local/lib/python3.12/site-packages/pandas/io/sql.py", line 2865, in has_table
    return len(self.execute(query, [name]).fetchall()) > 0
               ^^^^^^^^^^^^^^^^^^^^^^^^^^^
  File "/home/airflow/.local/lib/python3.12/site-packages/pandas/io/sql.py", line 2672, in execute
    cur = self.con.cursor()
          ^^^^^^^^^^^^^^^
AttributeError: 'Connection' object has no attribute 'cursor'
[2024-09-16T15:52:54.413+0000] {local_task_job_runner.py:266} INFO - Task exited with return code 1
[2024-09-16T15:52:54.462+0000] {taskinstance.py:3900} INFO - 0 downstream tasks scheduled from follow-on schedule check
[2024-09-16T15:52:54.472+0000] {local_task_job_runner.py:245} INFO - ::endgroup::
