[2024-09-10T08:21:25.844+0000] {local_task_job_runner.py:123} INFO - ::group::Pre task execution logs
[2024-09-10T08:21:25.860+0000] {taskinstance.py:2612} INFO - Dependencies all met for dep_context=non-requeueable deps ti=<TaskInstance: customer_product_bash.retailDataWithAirflow manual__2024-09-10T08:16:20.813166+00:00 [queued]>
[2024-09-10T08:21:25.866+0000] {taskinstance.py:2612} INFO - Dependencies all met for dep_context=requeueable deps ti=<TaskInstance: customer_product_bash.retailDataWithAirflow manual__2024-09-10T08:16:20.813166+00:00 [queued]>
[2024-09-10T08:21:25.867+0000] {taskinstance.py:2865} INFO - Starting attempt 2 of 2
[2024-09-10T08:21:25.879+0000] {taskinstance.py:2888} INFO - Executing <Task(BashOperator): retailDataWithAirflow> on 2024-09-10 08:16:20.813166+00:00
[2024-09-10T08:21:25.885+0000] {warnings.py:112} WARNING - /home/***/.local/lib/python3.12/site-packages/***/task/task_runner/standard_task_runner.py:70: DeprecationWarning: This process (pid=201) is multi-threaded, use of fork() may lead to deadlocks in the child.
  pid = os.fork()

[2024-09-10T08:21:25.886+0000] {standard_task_runner.py:72} INFO - Started process 202 to run task
[2024-09-10T08:21:25.886+0000] {standard_task_runner.py:104} INFO - Running: ['***', 'tasks', 'run', 'customer_product_bash', 'retailDataWithAirflow', 'manual__2024-09-10T08:16:20.813166+00:00', '--job-id', '31', '--raw', '--subdir', 'DAGS_FOLDER/retailData_dags.py', '--cfg-path', '/tmp/tmp2bo78arq']
[2024-09-10T08:21:25.886+0000] {standard_task_runner.py:105} INFO - Job 31: Subtask retailDataWithAirflow
[2024-09-10T08:21:25.921+0000] {task_command.py:467} INFO - Running <TaskInstance: customer_product_bash.retailDataWithAirflow manual__2024-09-10T08:16:20.813166+00:00 [running]> on host 8ab94618ab8b
[2024-09-10T08:21:25.980+0000] {taskinstance.py:3131} INFO - Exporting env vars: AIRFLOW_CTX_DAG_EMAIL='muhii.smta@gmail.com' AIRFLOW_CTX_DAG_OWNER='Muhii' AIRFLOW_CTX_DAG_ID='customer_product_bash' AIRFLOW_CTX_TASK_ID='retailDataWithAirflow' AIRFLOW_CTX_EXECUTION_DATE='2024-09-10T08:16:20.813166+00:00' AIRFLOW_CTX_TRY_NUMBER='2' AIRFLOW_CTX_DAG_RUN_ID='manual__2024-09-10T08:16:20.813166+00:00'
[2024-09-10T08:21:25.981+0000] {taskinstance.py:731} INFO - ::endgroup::
[2024-09-10T08:21:25.993+0000] {subprocess.py:63} INFO - Tmp dir root location: /tmp
[2024-09-10T08:21:25.993+0000] {subprocess.py:75} INFO - Running command: ['/usr/bin/bash', '-c', 'python /opt/***/dags/script/retailDataWithAirflow.py']
[2024-09-10T08:21:26.004+0000] {subprocess.py:86} INFO - Output:
[2024-09-10T08:21:26.717+0000] {subprocess.py:93} INFO - Traceback (most recent call last):
[2024-09-10T08:21:26.718+0000] {subprocess.py:93} INFO -   File "/opt/***/dags/script/retailDataWithAirflow.py", line 3, in <module>
[2024-09-10T08:21:26.719+0000] {subprocess.py:93} INFO -     from pandasql import sqldf
[2024-09-10T08:21:26.719+0000] {subprocess.py:93} INFO - ModuleNotFoundError: No module named 'pandasql'
[2024-09-10T08:21:26.775+0000] {subprocess.py:97} INFO - Command exited with return code 1
[2024-09-10T08:21:26.785+0000] {taskinstance.py:3310} ERROR - Task failed with exception
Traceback (most recent call last):
  File "/home/airflow/.local/lib/python3.12/site-packages/airflow/models/taskinstance.py", line 767, in _execute_task
    result = _execute_callable(context=context, **execute_callable_kwargs)
             ^^^^^^^^^^^^^^^^^^^^^^^^^^^^^^^^^^^^^^^^^^^^^^^^^^^^^^^^^^^^^
  File "/home/airflow/.local/lib/python3.12/site-packages/airflow/models/taskinstance.py", line 733, in _execute_callable
    return ExecutionCallableRunner(
           ^^^^^^^^^^^^^^^^^^^^^^^^
  File "/home/airflow/.local/lib/python3.12/site-packages/airflow/utils/operator_helpers.py", line 252, in run
    return self.func(*args, **kwargs)
           ^^^^^^^^^^^^^^^^^^^^^^^^^^
  File "/home/airflow/.local/lib/python3.12/site-packages/airflow/models/baseoperator.py", line 406, in wrapper
    return func(self, *args, **kwargs)
           ^^^^^^^^^^^^^^^^^^^^^^^^^^^
  File "/home/airflow/.local/lib/python3.12/site-packages/airflow/operators/bash.py", line 249, in execute
    raise AirflowException(
airflow.exceptions.AirflowException: Bash command failed. The command returned a non-zero exit code 1.
[2024-09-10T08:21:26.789+0000] {taskinstance.py:1225} INFO - Marking task as FAILED. dag_id=customer_product_bash, task_id=retailDataWithAirflow, run_id=manual__2024-09-10T08:16:20.813166+00:00, execution_date=20240910T081620, start_date=20240910T082125, end_date=20240910T082126
[2024-09-10T08:21:26.800+0000] {taskinstance.py:340} INFO - ::group::Post task execution logs
[2024-09-10T08:21:26.800+0000] {standard_task_runner.py:124} ERROR - Failed to execute job 31 for task retailDataWithAirflow (Bash command failed. The command returned a non-zero exit code 1.; 202)
Traceback (most recent call last):
  File "/home/airflow/.local/lib/python3.12/site-packages/airflow/task/task_runner/standard_task_runner.py", line 117, in _start_by_fork
    ret = args.func(args, dag=self.dag)
          ^^^^^^^^^^^^^^^^^^^^^^^^^^^^^
  File "/home/airflow/.local/lib/python3.12/site-packages/airflow/cli/cli_config.py", line 49, in command
    return func(*args, **kwargs)
           ^^^^^^^^^^^^^^^^^^^^^
  File "/home/airflow/.local/lib/python3.12/site-packages/airflow/utils/cli.py", line 115, in wrapper
    return f(*args, **kwargs)
           ^^^^^^^^^^^^^^^^^^
  File "/home/airflow/.local/lib/python3.12/site-packages/airflow/cli/commands/task_command.py", line 483, in task_run
    task_return_code = _run_task_by_selected_method(args, _dag, ti)
                       ^^^^^^^^^^^^^^^^^^^^^^^^^^^^^^^^^^^^^^^^^^^^
  File "/home/airflow/.local/lib/python3.12/site-packages/airflow/cli/commands/task_command.py", line 256, in _run_task_by_selected_method
    return _run_raw_task(args, ti)
           ^^^^^^^^^^^^^^^^^^^^^^^
  File "/home/airflow/.local/lib/python3.12/site-packages/airflow/cli/commands/task_command.py", line 341, in _run_raw_task
    return ti._run_raw_task(
           ^^^^^^^^^^^^^^^^^
  File "/home/airflow/.local/lib/python3.12/site-packages/airflow/utils/session.py", line 97, in wrapper
    return func(*args, session=session, **kwargs)
           ^^^^^^^^^^^^^^^^^^^^^^^^^^^^^^^^^^^^^^
  File "/home/airflow/.local/lib/python3.12/site-packages/airflow/models/taskinstance.py", line 3004, in _run_raw_task
    return _run_raw_task(
           ^^^^^^^^^^^^^^
  File "/home/airflow/.local/lib/python3.12/site-packages/airflow/models/taskinstance.py", line 273, in _run_raw_task
    TaskInstance._execute_task_with_callbacks(
  File "/home/airflow/.local/lib/python3.12/site-packages/airflow/models/taskinstance.py", line 3158, in _execute_task_with_callbacks
    result = self._execute_task(context, task_orig)
             ^^^^^^^^^^^^^^^^^^^^^^^^^^^^^^^^^^^^^^
  File "/home/airflow/.local/lib/python3.12/site-packages/airflow/models/taskinstance.py", line 3182, in _execute_task
    return _execute_task(self, context, task_orig)
           ^^^^^^^^^^^^^^^^^^^^^^^^^^^^^^^^^^^^^^^
  File "/home/airflow/.local/lib/python3.12/site-packages/airflow/models/taskinstance.py", line 767, in _execute_task
    result = _execute_callable(context=context, **execute_callable_kwargs)
             ^^^^^^^^^^^^^^^^^^^^^^^^^^^^^^^^^^^^^^^^^^^^^^^^^^^^^^^^^^^^^
  File "/home/airflow/.local/lib/python3.12/site-packages/airflow/models/taskinstance.py", line 733, in _execute_callable
    return ExecutionCallableRunner(
           ^^^^^^^^^^^^^^^^^^^^^^^^
  File "/home/airflow/.local/lib/python3.12/site-packages/airflow/utils/operator_helpers.py", line 252, in run
    return self.func(*args, **kwargs)
           ^^^^^^^^^^^^^^^^^^^^^^^^^^
  File "/home/airflow/.local/lib/python3.12/site-packages/airflow/models/baseoperator.py", line 406, in wrapper
    return func(self, *args, **kwargs)
           ^^^^^^^^^^^^^^^^^^^^^^^^^^^
  File "/home/airflow/.local/lib/python3.12/site-packages/airflow/operators/bash.py", line 249, in execute
    raise AirflowException(
airflow.exceptions.AirflowException: Bash command failed. The command returned a non-zero exit code 1.
[2024-09-10T08:21:26.823+0000] {local_task_job_runner.py:266} INFO - Task exited with return code 1
[2024-09-10T08:21:26.840+0000] {taskinstance.py:3900} INFO - 0 downstream tasks scheduled from follow-on schedule check
[2024-09-10T08:21:26.844+0000] {local_task_job_runner.py:245} INFO - ::endgroup::
